<?xml version="1.0" encoding="utf-8"?>
<!-- This URDF was automatically created by SolidWorks to URDF Exporter! Originally created by Stephen Brawner (brawner@gmail.com) 
     Commit Version: 1.6.0-4-g7f85cfe  Build Version: 1.6.7995.38578
     For more information, please see http://wiki.ros.org/sw_urdf_exporter -->
<robot
  name="NUDogv2">
  <link
    name="Body">
    <inertial>
      <origin
        xyz="-0.000211548270024517 -0.455924903723439 0.000570759184668047"
        rpy="0 0 0" />
      <mass
        value="7.3658966638029" />
      <inertia
        ixx="0.149737913482403"
        ixy="5.4566009501789E-07"
        ixz="-8.98208160406347E-13"
        iyy="0.0402457604729162"
        iyz="6.61238000974235E-11"
        izz="0.174510484060074" />
    </inertial>
    <visual>
      <origin
        xyz="0 0 0"
        rpy="0 0 0" />
      <geometry>
        <mesh
          filename="package://NUDogv2/meshes/Body.STL" />
      </geometry>
      <material
        name="">
        <color
          rgba="0.898039215686275 0.92156862745098 0.929411764705882 1" />
      </material>
    </visual>
    <collision>
      <origin
        xyz="0 0 0"
        rpy="0 0 0" />
      <geometry>
        <mesh
          filename="package://NUDogv2/meshes/Body.STL" />
      </geometry>
    </collision>
  </link>
  <link
    name="FR_1">
    <inertial>
      <origin
        xyz="-0.00176714022956819 0.000819654001147196 -0.0869564696489047"
        rpy="0 0 0" />
      <mass
        value="0.628306425345395" />
      <inertia
        ixx="0.00162123013189857"
        ixy="3.09906069011344E-06"
        ixz="-4.75997103606045E-08"
        iyy="0.00196763934294934"
        iyz="1.95223651534237E-07"
        izz="0.00053714617815285" />
    </inertial>
    <visual>
      <origin
        xyz="0 0 0"
        rpy="0 0 0" />
      <geometry>
        <mesh
          filename="package://NUDogv2/meshes/FR_1.STL" />
      </geometry>
      <material
        name="">
        <color
          rgba="0.792156862745098 0.819607843137255 0.933333333333333 1" />
      </material>
    </visual>
    <collision>
      <origin
        xyz="0 0 0"
        rpy="0 0 0" />
      <geometry>
        <mesh
          filename="package://NUDogv2/meshes/FR_1.STL" />
      </geometry>
    </collision>
  </link>
  <joint
    name="FR_Ad"
    type="revolute">
    <origin
      xyz="0.2 -0.19035 0"
      rpy="1.5708 -1.5708 0" />
    <parent
      link="Body" />
    <child
      link="FR_1" />
    <axis
      xyz="0 0 1" />
    <limit
      lower="-5"
      upper="5"
      effort="5"
      velocity="5" />
  </joint>
  <link
    name="FR_2">
    <inertial>
      <origin
        xyz="3.88653367643932E-05 -0.0440099346861161 -0.0372579060320848"
        rpy="0 0 0" />
      <mass
        value="0.955322691926052" />
      <inertia
        ixx="0.00135385236553172"
        ixy="-1.30915451823784E-06"
        ixz="5.40561671335864E-08"
        iyy="0.000526597180169"
        iyz="-1.02092745449935E-05"
        izz="0.00173666668506924" />
    </inertial>
    <visual>
      <origin
        xyz="0 0 0"
        rpy="0 0 0" />
      <geometry>
        <mesh
          filename="package://NUDogv2/meshes/FR_2.STL" />
      </geometry>
      <material
        name="">
        <color
          rgba="0.792156862745098 0.819607843137255 0.933333333333333 1" />
      </material>
    </visual>
    <collision>
      <origin
        xyz="0 0 0"
        rpy="0 0 0" />
      <geometry>
        <mesh
          filename="package://NUDogv2/meshes/FR_2.STL" />
      </geometry>
    </collision>
  </link>
  <joint
    name="FR_Hip"
    type="revolute">
    <origin
      xyz="0 -0.04635 -0.087"
      rpy="-1.5708 -0.78534 0" />
    <parent
      link="FR_1" />
    <child
      link="FR_2" />
    <axis
      xyz="0 0 1" />
    <limit
      lower="-5"
      upper="5"
      effort="5"
      velocity="5" />
  </joint>
  <link
    name="FR_3">
    <inertial>
      <origin
        xyz="0.105104655181102 -0.0640400377599924 -0.0238900020682811"
        rpy="0 0 0" />
      <mass
        value="0.423252165011343" />
      <inertia
        ixx="0.000289863197916037"
        ixy="0.000346854331370428"
        ixz="-1.45405032408544E-10"
        iyy="0.000644163854037181"
        iyz="3.97590266565829E-10"
        izz="0.000881301821186304" />
    </inertial>
    <visual>
      <origin
        xyz="0 0 0"
        rpy="0 0 0" />
      <geometry>
        <mesh
          filename="package://NUDogv2/meshes/FR_3.STL" />
      </geometry>
      <material
        name="">
        <color
          rgba="0.647058823529412 0.619607843137255 0.588235294117647 1" />
      </material>
    </visual>
    <collision>
      <origin
        xyz="0 0 0"
        rpy="0 0 0" />
      <geometry>
        <mesh
          filename="package://NUDogv2/meshes/FR_3.STL" />
      </geometry>
    </collision>
  </link>
  <joint
    name="FR_Knee"
    type="revolute">
    <origin
      xyz="0.00025 -0.3066 -0.083724"
      rpy="3.1416 0 2.7668" />
    <parent
      link="FR_2" />
    <child
      link="FR_3" />
    <axis
      xyz="0 0 1" />
    <limit
      lower="-5"
      upper="5"
      effort="5"
      velocity="5" />
  </joint>
  <link
    name="FL_1">
    <inertial>
      <origin
        xyz="-0.00176714526033473 -0.000819664820074811 -0.0870435354363932"
        rpy="0 0 0" />
      <mass
        value="0.628305321520991" />
      <inertia
        ixx="0.00162123211647625"
        ixy="-3.09902629211013E-06"
        ixz="4.82593164647364E-08"
        iyy="0.00196763709474905"
        iyz="1.95284679307444E-07"
        izz="0.000537145766319733" />
    </inertial>
    <visual>
      <origin
        xyz="0 0 0"
        rpy="0 0 0" />
      <geometry>
        <mesh
          filename="package://NUDogv2/meshes/FL_1.STL" />
      </geometry>
      <material
        name="">
        <color
          rgba="0.792156862745098 0.819607843137255 0.933333333333333 1" />
      </material>
    </visual>
    <collision>
      <origin
        xyz="0 0 0"
        rpy="0 0 0" />
      <geometry>
        <mesh
          filename="package://NUDogv2/meshes/FL_1.STL" />
      </geometry>
    </collision>
  </link>
  <joint
    name="FL_Ad"
    type="revolute">
    <origin
      xyz="-0.2 -0.19035 0"
      rpy="1.5708 -1.5708 0" />
    <parent
      link="Body" />
    <child
      link="FL_1" />
    <axis
      xyz="0 0 1" />
    <limit
      lower="-5"
      upper="5"
      effort="5"
      velocity="5" />
  </joint>
  <link
    name="FL_2">
    <inertial>
      <origin
        xyz="6.88107812843175E-05 -0.0439891388981822 -0.0372579049106987"
        rpy="0 0 0" />
      <mass
        value="0.955322588232291" />
      <inertia
        ixx="0.0013538244879862"
        ixy="-1.33675940094233E-06"
        ixz="-4.18973189634197E-07"
        iyy="0.000526625025236917"
        iyz="-1.0489729600724E-05"
        izz="0.00173666666385911" />
    </inertial>
    <visual>
      <origin
        xyz="0 0 0"
        rpy="0 0 0" />
      <geometry>
        <mesh
          filename="package://NUDogv2/meshes/FL_2.STL" />
      </geometry>
      <material
        name="">
        <color
          rgba="0.792156862745098 0.819607843137255 0.933333333333333 1" />
      </material>
    </visual>
    <collision>
      <origin
        xyz="0 0 0"
        rpy="0 0 0" />
      <geometry>
        <mesh
          filename="package://NUDogv2/meshes/FL_2.STL" />
      </geometry>
    </collision>
  </link>
  <joint
    name="FL_Hip"
    type="revolute">
    <origin
      xyz="0 0.04635 -0.087"
      rpy="-1.5708 0.78534 3.1416" />
    <parent
      link="FL_1" />
    <child
      link="FL_2" />
    <axis
      xyz="0 0 1" />
    <limit
      lower="-5"
      upper="5"
      effort="5"
      velocity="5" />
  </joint>
  <link
    name="FL_3">
    <inertial>
      <origin
        xyz="0.105303663557735 -0.0646580725694623 -0.636257997934563"
        rpy="0 0 0" />
      <mass
        value="0.42325216590946" />
      <inertia
        ixx="0.000289864448673439"
        ixy="0.000346854970340331"
        ixz="4.13807842263747E-10"
        iyy="0.000644162603951156"
        iyz="5.67488376831414E-11"
        izz="0.000881301821870475" />
    </inertial>
    <visual>
      <origin
        xyz="0 0 0"
        rpy="0 0 0" />
      <geometry>
        <mesh
          filename="package://NUDogv2/meshes/FL_3.STL" />
      </geometry>
      <material
        name="">
        <color
          rgba="0.192156862745098 0.203921568627451 0.203921568627451 1" />
      </material>
    </visual>
    <collision>
      <origin
        xyz="0 0 0"
        rpy="0 0 0" />
      <geometry>
        <mesh
          filename="package://NUDogv2/meshes/FL_3.STL" />
      </geometry>
    </collision>
  </link>
  <joint
    name="FL_Knee"
    type="revolute">
    <origin
      xyz="-0.00025 -0.3066 0.57642"
      rpy="0 0 0.37477" />
    <parent
      link="FL_2" />
    <child
      link="FL_3" />
    <axis
      xyz="0 0 1" />
    <limit
      lower="-5"
      upper="5"
      effort="5"
      velocity="5" />
  </joint>
  <link
    name="BR_1">
    <inertial>
      <origin
        xyz="0.00176714526033449 -0.000819664820074922 0.0870435354363934"
        rpy="0 0 0" />
      <mass
        value="0.628305321520992" />
      <inertia
        ixx="0.00162123211647626"
        ixy="3.09902629211019E-06"
        ixz="4.82593164644143E-08"
        iyy="0.00196763709474905"
        iyz="-1.95284679307826E-07"
        izz="0.000537145766319732" />
    </inertial>
    <visual>
      <origin
        xyz="0 0 0"
        rpy="0 0 0" />
      <geometry>
        <mesh
          filename="package://NUDogv2/meshes/BR_1.STL" />
      </geometry>
      <material
        name="">
        <color
          rgba="0.792156862745098 0.819607843137255 0.933333333333333 1" />
      </material>
    </visual>
    <collision>
      <origin
        xyz="0 0 0"
        rpy="0 0 0" />
      <geometry>
        <mesh
          filename="package://NUDogv2/meshes/BR_1.STL" />
      </geometry>
    </collision>
  </link>
  <joint
    name="BR_Ad"
    type="revolute">
    <origin
      xyz="0.2 -0.72405 0"
      rpy="1.5708 1.5708 0" />
    <parent
      link="Body" />
    <child
      link="BR_1" />
    <axis
      xyz="0 0 1" />
    <limit
      lower="-5"
      upper="5"
      effort="5"
      velocity="5" />
  </joint>
  <link
    name="BR_2">
    <inertial>
      <origin
        xyz="3.88641970533454E-05 -0.0440099426546752 -0.0372579046962084"
        rpy="0 0 0" />
      <mass
        value="0.955322561394478" />
      <inertia
        ixx="0.00135385235013848"
        ixy="-1.3091467422203E-06"
        ixz="5.40634689426503E-08"
        iyy="0.000526597159136609"
        iyz="-1.02092692452132E-05"
        izz="0.00173666666337671" />
    </inertial>
    <visual>
      <origin
        xyz="0 0 0"
        rpy="0 0 0" />
      <geometry>
        <mesh
          filename="package://NUDogv2/meshes/BR_2.STL" />
      </geometry>
      <material
        name="">
        <color
          rgba="0.792156862745098 0.819607843137255 0.933333333333333 1" />
      </material>
    </visual>
    <collision>
      <origin
        xyz="0 0 0"
        rpy="0 0 0" />
      <geometry>
        <mesh
          filename="package://NUDogv2/meshes/BR_2.STL" />
      </geometry>
    </collision>
  </link>
  <joint
    name="BR_Hip"
    type="revolute">
    <origin
      xyz="0 0.04635 0.087"
      rpy="-1.5708 -0.78534 -3.1416" />
    <parent
      link="BR_1" />
    <child
      link="BR_2" />
    <axis
      xyz="0 0 1" />
    <limit
      lower="-5"
      upper="5"
      effort="5"
      velocity="5" />
  </joint>
  <link
    name="BR_3">
    <inertial>
      <origin
        xyz="-0.120728218455898 -0.0239334962150342 0.0175400020693254"
        rpy="0 0 0" />
      <mass
        value="0.423252165078239" />
      <inertia
        ixx="0.000107613075131097"
        ixy="-0.000150071589098105"
        ixz="-2.73415295467842E-10"
        iyy="0.000826413976828154"
        iyz="-3.23211280137644E-10"
        izz="0.000881301821191495" />
    </inertial>
    <visual>
      <origin
        xyz="0 0 0"
        rpy="0 0 0" />
      <geometry>
        <mesh
          filename="package://NUDogv2/meshes/BR_3.STL" />
      </geometry>
      <material
        name="">
        <color
          rgba="0.647058823529412 0.619607843137255 0.588235294117647 1" />
      </material>
    </visual>
    <collision>
      <origin
        xyz="0 0 0"
        rpy="0 0 0" />
      <geometry>
        <mesh
          filename="package://NUDogv2/meshes/BR_3.STL" />
      </geometry>
    </collision>
  </link>
  <joint
    name="BR_Knee"
    type="revolute">
    <origin
      xyz="0.00025 -0.3066 -0.077374"
      rpy="0 0 -0.023244" />
    <parent
      link="BR_2" />
    <child
      link="BR_3" />
    <axis
      xyz="0 0 1" />
    <limit
      lower="-5"
      upper="5"
      effort="5"
      velocity="5" />
  </joint>
  <link
    name="BL_1">
    <inertial>
      <origin
        xyz="0.00176714022956802 0.000819654001147169 0.0869564696489052"
        rpy="0 0 0" />
      <mass
        value="0.628306425345398" />
      <inertia
        ixx="0.00162123013189857"
        ixy="-3.09906069011293E-06"
        ixz="-4.75997103593867E-08"
        iyy="0.00196763934294934"
        iyz="-1.95223651534071E-07"
        izz="0.000537146178152854" />
    </inertial>
    <visual>
      <origin
        xyz="0 0 0"
        rpy="0 0 0" />
      <geometry>
        <mesh
          filename="package://NUDogv2/meshes/BL_1.STL" />
      </geometry>
      <material
        name="">
        <color
          rgba="0.792156862745098 0.819607843137255 0.933333333333333 1" />
      </material>
    </visual>
    <collision>
      <origin
        xyz="0 0 0"
        rpy="0 0 0" />
      <geometry>
        <mesh
          filename="package://NUDogv2/meshes/BL_1.STL" />
      </geometry>
    </collision>
  </link>
  <joint
    name="BL_Ad"
    type="revolute">
    <origin
      xyz="-0.2 -0.72405 0"
      rpy="1.5708 1.5708 0" />
    <parent
      link="Body" />
    <child
      link="BL_1" />
    <axis
      xyz="0 0 1" />
    <limit
      lower="-5"
      upper="5"
      effort="5"
      velocity="5" />
  </joint>
  <link
    name="BL_2">
    <inertial>
      <origin
        xyz="6.8810906338812E-05 -0.0439891393180145 -0.0372579044789478"
        rpy="0 0 0" />
      <mass
        value="0.955322565334975" />
      <inertia
        ixx="0.00135382448511837"
        ixy="-1.33676015052377E-06"
        ixz="-4.18972136940502E-07"
        iyy="0.00052662502351927"
        iyz="-1.04897298938561E-05"
        izz="0.00173666666193975" />
    </inertial>
    <visual>
      <origin
        xyz="0 0 0"
        rpy="0 0 0" />
      <geometry>
        <mesh
          filename="package://NUDogv2/meshes/BL_2.STL" />
      </geometry>
      <material
        name="">
        <color
          rgba="0.792156862745098 0.819607843137255 0.933333333333333 1" />
      </material>
    </visual>
    <collision>
      <origin
        xyz="0 0 0"
        rpy="0 0 0" />
      <geometry>
        <mesh
          filename="package://NUDogv2/meshes/BL_2.STL" />
      </geometry>
    </collision>
  </link>
  <joint
    name="BL_Hip"
    type="revolute">
    <origin
      xyz="0 -0.04635 0.087"
      rpy="-1.5708 0.78534 0" />
    <parent
      link="BL_1" />
    <child
      link="BL_2" />
    <axis
      xyz="0 0 1" />
    <limit
      lower="-5"
      upper="5"
      effort="5"
      velocity="5" />
  </joint>
  <link
    name="BL_3">
    <inertial>
      <origin
        xyz="0.00025502438265268 -0.123077412862254 -0.000270702067466488"
        rpy="0 0 0" />
      <mass
        value="0.423252166006372" />
      <inertia
        ixx="0.000856487743888114"
        ixy="7.02282585465222E-10"
        ixz="2.64445601179726E-10"
        iyy="7.75393087370826E-05"
        iyz="3.2330608030048E-10"
        izz="0.000881301821869342" />
    </inertial>
    <visual>
      <origin
        xyz="0 0 0"
        rpy="0 0 0" />
      <geometry>
        <mesh
          filename="package://NUDogv2/meshes/BL_3.STL" />
      </geometry>
      <material
        name="">
        <color
          rgba="0.192156862745098 0.203921568627451 0.203921568627451 1" />
      </material>
    </visual>
    <collision>
      <origin
        xyz="0 0 0"
        rpy="0 0 0" />
      <geometry>
        <mesh
          filename="package://NUDogv2/meshes/BL_3.STL" />
      </geometry>
    </collision>
  </link>
  <joint
    name="BL_Knee"
    type="revolute">
    <origin
      xyz="0.00025 -0.3066 -0.060105"
      rpy="3.1416 0 -1.7453" />
    <parent
      link="BL_2" />
    <child
      link="BL_3" />
    <axis
      xyz="0 0 1" />
    <limit
      lower="-5"
      upper="5"
      effort="5"
      velocity="5" />
  </joint>
</robot>