<?xml version="1.0" encoding="utf-8"?>
<!-- This URDF was automatically created by SolidWorks to URDF Exporter! Originally created by Stephen Brawner (brawner@gmail.com) 
     Commit Version: 1.6.0-4-g7f85cfe  Build Version: 1.6.7995.38578
     For more information, please see http://wiki.ros.org/sw_urdf_exporter -->
<robot
  name="NUDogv4">
  <link
    name="Body">
    <inertial>
      <origin
        xyz="-0.000211548270024514 -0.455924903723439 0.520570759184668"
        rpy="0 0 0" />
      <mass
        value="7.3658966638029" />
      <inertia
        ixx="0.149737913482403"
        ixy="5.45660095017892E-07"
        ixz="-8.98208157193702E-13"
        iyy="0.0402457604729162"
        iyz="6.61238000966295E-11"
        izz="0.174510484060074" />
    </inertial>
    <visual>
      <origin
        xyz="0 0 0"
        rpy="0 0 0" />
      <geometry>
        <mesh
          filename="package://NUDogv4/meshes/Body.STL" />
      </geometry>
      <material
        name="">
        <color
          rgba="0.898039215686275 0.92156862745098 0.929411764705882 1" />
      </material>
    </visual>
    <collision>
      <origin
        xyz="0 0 0"
        rpy="0 0 0" />
      <geometry>
        <mesh
          filename="package://NUDogv4/meshes/Body.STL" />
      </geometry>
    </collision>
  </link>
  <link
    name="FR_1">
    <inertial>
      <origin
        xyz="-0.00176714022956819 0.000819654001147141 -0.0869564696489047"
        rpy="0 0 0" />
      <mass
        value="0.628306425345395" />
      <inertia
        ixx="0.00162123013189857"
        ixy="3.09906069011344E-06"
        ixz="-4.75997103606054E-08"
        iyy="0.00196763934294934"
        iyz="1.95223651534245E-07"
        izz="0.00053714617815285" />
    </inertial>
    <visual>
      <origin
        xyz="0 0 0"
        rpy="0 0 0" />
      <geometry>
        <mesh
          filename="package://NUDogv4/meshes/FR_1.STL" />
      </geometry>
      <material
        name="">
        <color
          rgba="0.792156862745098 0.819607843137255 0.933333333333333 1" />
      </material>
    </visual>
    <collision>
      <origin
        xyz="0 0 0"
        rpy="0 0 0" />
      <geometry>
        <mesh
          filename="package://NUDogv4/meshes/FR_1.STL" />
      </geometry>
    </collision>
  </link>
  <joint
    name="FR_Ad"
    type="revolute">
    <origin
      xyz="0.2 -0.19035 0.52"
      rpy="1.5708 -1.5708 0" />
    <parent
      link="Body" />
    <child
      link="FR_1" />
    <axis
      xyz="1 0 0" />
    <limit
      lower="-5"
      upper="5"
      effort="5"
      velocity="5" />
  </joint>
  <link
    name="FR_2">
    <inertial>
      <origin
        xyz="3.88653367526109E-05 -0.04400993464036 -0.0372579060272206"
        rpy="0 0 0" />
      <mass
        value="0.955322691719821" />
      <inertia
        ixx="0.00135385236540019"
        ixy="-1.30915451927057E-06"
        ixz="5.4056167079876E-08"
        iyy="0.000526597180168496"
        iyz="-1.02092745441853E-05"
        izz="0.00173666668493754" />
    </inertial>
    <visual>
      <origin
        xyz="0 0 0"
        rpy="0 0 0" />
      <geometry>
        <mesh
          filename="package://NUDogv4/meshes/FR_2.STL" />
      </geometry>
      <material
        name="">
        <color
          rgba="0.792156862745098 0.819607843137255 0.933333333333333 1" />
      </material>
    </visual>
    <collision>
      <origin
        xyz="0 0 0"
        rpy="0 0 0" />
      <geometry>
        <mesh
          filename="package://NUDogv4/meshes/FR_2.STL" />
      </geometry>
    </collision>
  </link>
  <joint
    name="FR_Hip"
    type="revolute">
    <origin
      xyz="0 -0.04635 -0.087"
      rpy="-1.5708 -0.78534 0" />
    <parent
      link="FR_1" />
    <child
      link="FR_2" />
    <axis
      xyz="0 1 0" />
    <limit
      lower="-5"
      upper="5"
      effort="5"
      velocity="5" />
  </joint>
  <link
    name="FR_3">
    <inertial>
      <origin
        xyz="0.0707933992377545 -0.0431437715996056 -0.0239079279277191"
        rpy="0 0 0" />
      <mass
        value="0.343745474492043" />
      <inertia
        ixx="0.00026733692341714"
        ixy="0.000338574960072996"
        ixz="-1.45406305589385E-10"
        iyy="0.00061318050300175"
        iyz="3.97591083581222E-10"
        izz="0.000845273984778606" />
    </inertial>
    <visual>
      <origin
        xyz="0 0 0"
        rpy="0 0 0" />
      <geometry>
        <mesh
          filename="package://NUDogv4/meshes/FR_3.STL" />
      </geometry>
      <material
        name="">
        <color
          rgba="0.647058823529412 0.619607843137255 0.588235294117647 1" />
      </material>
    </visual>
    <collision>
      <origin
        xyz="0 0 0"
        rpy="0 0 0" />
      <geometry>
        <mesh
          filename="package://NUDogv4/meshes/FR_3.STL" />
      </geometry>
    </collision>
  </link>
  <joint
    name="FR_Knee"
    type="revolute">
    <origin
      xyz="0.00025 -0.3066 -0.083724"
      rpy="3.1416 0 2.7668" />
    <parent
      link="FR_2" />
    <child
      link="FR_3" />
    <axis
      xyz="0 1 0" />
    <limit
      lower="-5"
      upper="5"
      effort="5"
      velocity="5" />
  </joint>
  <link
    name="FR_F">
    <inertial>
      <origin
        xyz="0.253448635764736 -0.154384597186353 -0.0238124999987328"
        rpy="0 0 0" />
      <mass
        value="0.0795066905193" />
      <inertia
        ixx="2.25262744988979E-05"
        ixy="8.27937129743171E-06"
        ixz="1.273180932029E-15"
        iyy="3.09833510354308E-05"
        iyz="-8.17015249736315E-16"
        izz="3.60278364076971E-05" />
    </inertial>
    <visual>
      <origin
        xyz="0 0 0"
        rpy="0 0 0" />
      <geometry>
        <mesh
          filename="package://NUDogv4/meshes/FR_F.STL" />
      </geometry>
      <material
        name="">
        <color
          rgba="0.792156862745098 0.819607843137255 0.933333333333333 1" />
      </material>
    </visual>
    <collision>
      <origin
        xyz="0 0 0"
        rpy="0 0 0" />
      <geometry>
        <mesh
          filename="package://NUDogv4/meshes/FR_F.STL" />
      </geometry>
    </collision>
  </link>
  <joint
    name="FR_Ank"
    type="fixed">
    <origin
      xyz="0 0 0"
      rpy="0 0 0" />
    <parent
      link="FR_3" />
    <child
      link="FR_F" />
    <axis
      xyz="0 0 0" />
  </joint>
  <link
    name="FL_1">
    <inertial>
      <origin
        xyz="-0.00176714526033473 -0.000819664820074839 -0.0870435354363931"
        rpy="0 0 0" />
      <mass
        value="0.628305321520991" />
      <inertia
        ixx="0.00162123211647626"
        ixy="-3.09902629211013E-06"
        ixz="4.82593164647273E-08"
        iyy="0.00196763709474905"
        iyz="1.9528467930745E-07"
        izz="0.000537145766319732" />
    </inertial>
    <visual>
      <origin
        xyz="0 0 0"
        rpy="0 0 0" />
      <geometry>
        <mesh
          filename="package://NUDogv4/meshes/FL_1.STL" />
      </geometry>
      <material
        name="">
        <color
          rgba="0.792156862745098 0.819607843137255 0.933333333333333 1" />
      </material>
    </visual>
    <collision>
      <origin
        xyz="0 0 0"
        rpy="0 0 0" />
      <geometry>
        <mesh
          filename="package://NUDogv4/meshes/FL_1.STL" />
      </geometry>
    </collision>
  </link>
  <joint
    name="FL_Ad"
    type="revolute">
    <origin
      xyz="-0.2 -0.19035 0.52"
      rpy="1.5708 -1.5708 0" />
    <parent
      link="Body" />
    <child
      link="FL_1" />
    <axis
      xyz="1 0 0" />
    <limit
      lower="-5"
      upper="5"
      effort="5"
      velocity="5" />
  </joint>
  <link
    name="FL_2">
    <inertial>
      <origin
        xyz="6.88107812813338E-05 -0.0439891388524125 -0.0372579049058313"
        rpy="0 0 0" />
      <mass
        value="0.955322588026012" />
      <inertia
        ixx="0.00135382448785464"
        ixy="-1.33675940199748E-06"
        ixz="-4.18973189680303E-07"
        iyy="0.000526625025236412"
        iyz="-1.04897295999323E-05"
        izz="0.0017366666637274" />
    </inertial>
    <visual>
      <origin
        xyz="0 0 0"
        rpy="0 0 0" />
      <geometry>
        <mesh
          filename="package://NUDogv4/meshes/FL_2.STL" />
      </geometry>
      <material
        name="">
        <color
          rgba="0.792156862745098 0.819607843137255 0.933333333333333 1" />
      </material>
    </visual>
    <collision>
      <origin
        xyz="0 0 0"
        rpy="0 0 0" />
      <geometry>
        <mesh
          filename="package://NUDogv4/meshes/FL_2.STL" />
      </geometry>
    </collision>
  </link>
  <joint
    name="FL_Hip"
    type="revolute">
    <origin
      xyz="0 0.04635 -0.087"
      rpy="-1.5708 0.78534 3.1416" />
    <parent
      link="FL_1" />
    <child
      link="FL_2" />
    <axis
      xyz="0 1 0" />
    <limit
      lower="-5"
      upper="5"
      effort="5"
      velocity="5" />
  </joint>
  <link
    name="FL_3">
    <inertial>
      <origin
        xyz="0.071087800675071 -0.0436059712263585 -0.636240072076417"
        rpy="0 0 0" />
      <mass
        value="0.34374547539016" />
      <inertia
        ixx="0.000267338174174542"
        ixy="0.0003385755990429"
        ixz="4.13806569115431E-10"
        iyy="0.000613179252915724"
        iyz="5.67496546800636E-11"
        izz="0.000845273985462778" />
    </inertial>
    <visual>
      <origin
        xyz="0 0 0"
        rpy="0 0 0" />
      <geometry>
        <mesh
          filename="package://NUDogv4/meshes/FL_3.STL" />
      </geometry>
      <material
        name="">
        <color
          rgba="0.192156862745098 0.203921568627451 0.203921568627451 1" />
      </material>
    </visual>
    <collision>
      <origin
        xyz="0 0 0"
        rpy="0 0 0" />
      <geometry>
        <mesh
          filename="package://NUDogv4/meshes/FL_3.STL" />
      </geometry>
    </collision>
  </link>
  <joint
    name="FL_Knee"
    type="revolute">
    <origin
      xyz="-0.00025 -0.3066 0.57642"
      rpy="0 0 0.37477" />
    <parent
      link="FL_2" />
    <child
      link="FL_3" />
    <axis
      xyz="0 1 0" />
    <limit
      lower="-5"
      upper="5"
      effort="5"
      velocity="5" />
  </joint>
  <link
    name="FL_F">
    <inertial>
      <origin
        xyz="0.00065000000428983 -0.296766561996807 -0.00019320000126799"
        rpy="0 0 0" />
      <mass
        value="0.0795066905193" />
      <inertia
        ixx="3.60515070703525E-05"
        ixy="5.22651431004604E-15"
        ixz="-3.21100669825951E-17"
        iyy="1.74581184639763E-05"
        iyz="1.51240202779392E-15"
        izz="3.60278364076971E-05" />
    </inertial>
    <visual>
      <origin
        xyz="0 0 0"
        rpy="0 0 0" />
      <geometry>
        <mesh
          filename="package://NUDogv4/meshes/FL_F.STL" />
      </geometry>
      <material
        name="">
        <color
          rgba="0.792156862745098 0.819607843137255 0.933333333333333 1" />
      </material>
    </visual>
    <collision>
      <origin
        xyz="0 0 0"
        rpy="0 0 0" />
      <geometry>
        <mesh
          filename="package://NUDogv4/meshes/FL_F.STL" />
      </geometry>
    </collision>
  </link>
  <joint
    name="FL_Ank"
    type="fixed">
    <origin
      xyz="0.0004653 -0.00018303 -0.63653"
      rpy="3.1416 0 -2.1201" />
    <parent
      link="FL_3" />
    <child
      link="FL_F" />
    <axis
      xyz="0 0 0" />
  </joint>
  <link
    name="BR_1">
    <inertial>
      <origin
        xyz="0.00176714526033449 -0.000819664820074922 0.0870435354363934"
        rpy="0 0 0" />
      <mass
        value="0.628305321520992" />
      <inertia
        ixx="0.00162123211647625"
        ixy="3.09902629211019E-06"
        ixz="4.82593164643971E-08"
        iyy="0.00196763709474905"
        iyz="-1.95284679307816E-07"
        izz="0.000537145766319733" />
    </inertial>
    <visual>
      <origin
        xyz="0 0 0"
        rpy="0 0 0" />
      <geometry>
        <mesh
          filename="package://NUDogv4/meshes/BR_1.STL" />
      </geometry>
      <material
        name="">
        <color
          rgba="0.792156862745098 0.819607843137255 0.933333333333333 1" />
      </material>
    </visual>
    <collision>
      <origin
        xyz="0 0 0"
        rpy="0 0 0" />
      <geometry>
        <mesh
          filename="package://NUDogv4/meshes/BR_1.STL" />
      </geometry>
    </collision>
  </link>
  <joint
    name="BR_Ad"
    type="revolute">
    <origin
      xyz="0.2 -0.72405 0.52"
      rpy="1.5708 1.5708 0" />
    <parent
      link="Body" />
    <child
      link="BR_1" />
    <axis
      xyz="1 0 0" />
    <limit
      lower="-5"
      upper="5"
      effort="5"
      velocity="5" />
  </joint>
  <link
    name="BR_2">
    <inertial>
      <origin
        xyz="3.88641970419101E-05 -0.0440099426088791 -0.0372579046913361"
        rpy="0 0 0" />
      <mass
        value="0.955322561188065" />
      <inertia
        ixx="0.00135385235000691"
        ixy="-1.30914674325349E-06"
        ixz="5.40634688879456E-08"
        iyy="0.000526597159136105"
        iyz="-1.02092692444392E-05"
        izz="0.00173666666324501" />
    </inertial>
    <visual>
      <origin
        xyz="0 0 0"
        rpy="0 0 0" />
      <geometry>
        <mesh
          filename="package://NUDogv4/meshes/BR_2.STL" />
      </geometry>
      <material
        name="">
        <color
          rgba="0.792156862745098 0.819607843137255 0.933333333333333 1" />
      </material>
    </visual>
    <collision>
      <origin
        xyz="0 0 0"
        rpy="0 0 0" />
      <geometry>
        <mesh
          filename="package://NUDogv4/meshes/BR_2.STL" />
      </geometry>
    </collision>
  </link>
  <joint
    name="BR_Hip"
    type="revolute">
    <origin
      xyz="0 0.04635 0.087"
      rpy="-1.5708 -0.78534 -3.1416" />
    <parent
      link="BR_1" />
    <child
      link="BR_2" />
    <axis
      xyz="0 1 0" />
    <limit
      lower="-5"
      upper="5"
      effort="5"
      velocity="5" />
  </joint>
  <link
    name="BR_3">
    <inertial>
      <origin
        xyz="-0.0813199475538939 -0.0161293685843369 0.0175579279290014"
        rpy="0 0 0" />
      <mass
        value="0.343745474558939" />
      <inertia
        ixx="8.94370936715579E-05"
        ixy="-0.000146489386094053"
        ixz="-2.7341677210441E-10"
        iyy="0.000791080332753365"
        iyz="-3.23211608813054E-10"
        izz="0.000845273984783798" />
    </inertial>
    <visual>
      <origin
        xyz="0 0 0"
        rpy="0 0 0" />
      <geometry>
        <mesh
          filename="package://NUDogv4/meshes/BR_3.STL" />
      </geometry>
      <material
        name="">
        <color
          rgba="0.647058823529412 0.619607843137255 0.588235294117647 1" />
      </material>
    </visual>
    <collision>
      <origin
        xyz="0 0 0"
        rpy="0 0 0" />
      <geometry>
        <mesh
          filename="package://NUDogv4/meshes/BR_3.STL" />
      </geometry>
    </collision>
  </link>
  <joint
    name="BR_Knee"
    type="revolute">
    <origin
      xyz="0.00025 -0.3066 -0.077374"
      rpy="0 0 -0.023244" />
    <parent
      link="BR_2" />
    <child
      link="BR_3" />
    <axis
      xyz="0 1 0" />
    <limit
      lower="-5"
      upper="5"
      effort="5"
      velocity="5" />
  </joint>
  <link
    name="BR_F">
    <inertial>
      <origin
        xyz="-0.291109034136664 -0.0576744749730584 0.0174624999987329"
        rpy="0 0 0" />
      <mass
        value="0.0795066905193" />
      <inertia
        ixx="1.8175981459539E-05"
        ixy="-3.58220300405169E-06"
        ixz="1.47663654585947E-15"
        iyy="3.53336440747897E-05"
        iyz="3.2867529280903E-16"
        izz="3.60278364076971E-05" />
    </inertial>
    <visual>
      <origin
        xyz="0 0 0"
        rpy="0 0 0" />
      <geometry>
        <mesh
          filename="package://NUDogv4/meshes/BR_F.STL" />
      </geometry>
      <material
        name="">
        <color
          rgba="0.792156862745098 0.819607843137255 0.933333333333333 1" />
      </material>
    </visual>
    <collision>
      <origin
        xyz="0 0 0"
        rpy="0 0 0" />
      <geometry>
        <mesh
          filename="package://NUDogv4/meshes/BR_F.STL" />
      </geometry>
    </collision>
  </link>
  <joint
    name="BR_Ank"
    type="fixed">
    <origin
      xyz="0 0 0"
      rpy="0 0 0" />
    <parent
      link="BR_3" />
    <child
      link="BR_F" />
    <axis
      xyz="0 0 0" />
  </joint>
  <link
    name="BL_1">
    <inertial>
      <origin
        xyz="0.00176714022956802 0.000819654001147085 0.0869564696489052"
        rpy="0 0 0" />
      <mass
        value="0.628306425345398" />
      <inertia
        ixx="0.00162123013189857"
        ixy="-3.09906069011292E-06"
        ixz="-4.75997103593867E-08"
        iyy="0.00196763934294934"
        iyz="-1.9522365153407E-07"
        izz="0.000537146178152853" />
    </inertial>
    <visual>
      <origin
        xyz="0 0 0"
        rpy="0 0 0" />
      <geometry>
        <mesh
          filename="package://NUDogv4/meshes/BL_1.STL" />
      </geometry>
      <material
        name="">
        <color
          rgba="0.792156862745098 0.819607843137255 0.933333333333333 1" />
      </material>
    </visual>
    <collision>
      <origin
        xyz="0 0 0"
        rpy="0 0 0" />
      <geometry>
        <mesh
          filename="package://NUDogv4/meshes/BL_1.STL" />
      </geometry>
    </collision>
  </link>
  <joint
    name="BL_Ad"
    type="revolute">
    <origin
      xyz="-0.2 -0.72405 0.52"
      rpy="1.5708 1.5708 0" />
    <parent
      link="Body" />
    <child
      link="BL_1" />
    <axis
      xyz="1 0 0" />
    <limit
      lower="-5"
      upper="5"
      effort="5"
      velocity="5" />
  </joint>
  <link
    name="BL_2">
    <inertial>
      <origin
        xyz="6.8810906333816E-05 -0.0439891392721496 -0.0372579044740784"
        rpy="0 0 0" />
      <mass
        value="0.955322565128304" />
      <inertia
        ixx="0.00135382448498683"
        ixy="-1.33676015154965E-06"
        ixz="-4.18972136971195E-07"
        iyy="0.000526625023518765"
        iyz="-1.04897298930058E-05"
        izz="0.00173666666180803" />
    </inertial>
    <visual>
      <origin
        xyz="0 0 0"
        rpy="0 0 0" />
      <geometry>
        <mesh
          filename="package://NUDogv4/meshes/BL_2.STL" />
      </geometry>
      <material
        name="">
        <color
          rgba="0.792156862745098 0.819607843137255 0.933333333333333 1" />
      </material>
    </visual>
    <collision>
      <origin
        xyz="0 0 0"
        rpy="0 0 0" />
      <geometry>
        <mesh
          filename="package://NUDogv4/meshes/BL_2.STL" />
      </geometry>
    </collision>
  </link>
  <joint
    name="BL_Hip"
    type="revolute">
    <origin
      xyz="0 -0.04635 0.087"
      rpy="-1.5708 0.78534 0" />
    <parent
      link="BL_1" />
    <child
      link="BL_2" />
    <axis
      xyz="0 1 0" />
    <limit
      lower="-5"
      upper="5"
      effort="5"
      velocity="5" />
  </joint>
  <link
    name="BL_3">
    <inertial>
      <origin
        xyz="0.000163668403443173 -0.0829039403031343 -0.000288627926077922"
        rpy="0 0 0" />
      <mass
        value="0.343745475487072" />
      <inertia
        ixx="0.000820436236817762"
        ixy="7.02277358980558E-10"
        ixz="2.64445633291052E-10"
        iyy="6.00811902731063E-05"
        iyz="3.2330456790468E-10"
        izz="0.000845273985461645" />
    </inertial>
    <visual>
      <origin
        xyz="0 0 0"
        rpy="0 0 0" />
      <geometry>
        <mesh
          filename="package://NUDogv4/meshes/BL_3.STL" />
      </geometry>
      <material
        name="">
        <color
          rgba="0.192156862745098 0.203921568627451 0.203921568627451 1" />
      </material>
    </visual>
    <collision>
      <origin
        xyz="0 0 0"
        rpy="0 0 0" />
      <geometry>
        <mesh
          filename="package://NUDogv4/meshes/BL_3.STL" />
      </geometry>
    </collision>
  </link>
  <joint
    name="BL_Knee"
    type="revolute">
    <origin
      xyz="0.00025 -0.3066 -0.060105"
      rpy="3.1416 0 -1.7453" />
    <parent
      link="BL_2" />
    <child
      link="BL_3" />
    <axis
      xyz="0 1 0" />
    <limit
      lower="-5"
      upper="5"
      effort="5"
      velocity="5" />
  </joint>
  <link
    name="BL_F">
    <inertial>
      <origin
        xyz="0.000650000004288609 -0.296766561996807 -0.00019320000126799"
        rpy="0 0 0" />
      <mass
        value="0.0795066905193" />
      <inertia
        ixx="3.60515070703525E-05"
        ixy="5.22642367752069E-15"
        ixz="-3.2111301130762E-17"
        iyy="1.74581184639763E-05"
        iyz="1.51239582880729E-15"
        izz="3.60278364076971E-05" />
    </inertial>
    <visual>
      <origin
        xyz="0 0 0"
        rpy="0 0 0" />
      <geometry>
        <mesh
          filename="package://NUDogv4/meshes/BL_F.STL" />
      </geometry>
      <material
        name="">
        <color
          rgba="0.792156862745098 0.819607843137255 0.933333333333333 1" />
      </material>
    </visual>
    <collision>
      <origin
        xyz="0 0 0"
        rpy="0 0 0" />
      <geometry>
        <mesh
          filename="package://NUDogv4/meshes/BL_F.STL" />
      </geometry>
    </collision>
  </link>
  <joint
    name="BL_Ank"
    type="fixed">
    <origin
      xyz="0 0 0"
      rpy="0 0 0" />
    <parent
      link="BL_3" />
    <child
      link="BL_F" />
    <axis
      xyz="0 0 0" />
  </joint>
</robot>
