<?xml version="1.0" encoding="utf-8"?>
<!-- This URDF was automatically created by SolidWorks to URDF Exporter! Originally created by Stephen Brawner (brawner@gmail.com) 
     Commit Version: 1.6.0-4-g7f85cfe  Build Version: 1.6.7995.38578
     For more information, please see http://wiki.ros.org/sw_urdf_exporter -->
<robot
  name="nuDogv6">
  <link
    name="Body">
<!--    <inertial>
      <origin
        xyz="-0.000211548270024517 -0.455924903723439 0.520570759184668"
        rpy="0 0 0" />
      <mass
        value="7.3658966638029" />
      <inertia
        ixx="0.149737913482403"
        ixy="5.4566009501789E-07"
        ixz="-8.98208147226468E-13"
        iyy="0.0402457604729162"
        iyz="6.61238000992775E-11"
        izz="0.174510484060074" />
    </inertial>
  -->  <visual>
      <origin
        xyz="0 0 0"
        rpy="0 0 0" />
      <geometry>
        <mesh
          filename="package://nuDogv6/meshes/Body.STL" />
      </geometry>
      <material
        name="">
        <color
          rgba="0.898039215686275 0.92156862745098 0.929411764705882 1" />
      </material>
    </visual>
    <collision>
      <origin
        xyz="0 0 0"
        rpy="0 0 0" />
      <geometry>
        <mesh
          filename="package://nuDogv6/meshes/Body.STL" />
      </geometry>
    </collision>
  </link>
  <link
    name="FR_1">
    <inertial>
      <origin
        xyz="-0.0966409614939924 -0.00092652871580623 -0.00199755966138084"
        rpy="0 0 0" />
      <mass
        value="0.555831049727415" />
      <inertia
        ixx="0.000517471328500522"
        ixy="1.30651234728158E-05"
        ixz="1.88139667336094E-05"
        iyy="0.00142784729581039"
        iyz="-2.61322353699576E-06"
        izz="0.00108178759053029" />
    </inertial>
    <visual>
      <origin
        xyz="0 0 0"
        rpy="0 0 0" />
      <geometry>
        <mesh
          filename="package://nuDogv6/meshes/FR_1.STL" />
      </geometry>
      <material
        name="">
        <color
          rgba="0.792156862745098 0.819607843137255 0.933333333333333 1" />
      </material>
    </visual>
    <collision>
      <origin
        xyz="0 0 0"
        rpy="0 0 0" />
      <geometry>
        <mesh
          filename="package://nuDogv6/meshes/FR_1.STL" />
      </geometry>
    </collision>
  </link>
  <joint
    name="FR_Ad"
    type="revolute">
    <origin
      xyz="0.2 -0.19035 0.52"
      rpy="0 0 -1.5708" />
    <parent
      link="Body" />
    <child
      link="FR_1" />
    <axis
      xyz="1 0 0" />
    <limit
      lower="-5"
      upper="5"
      effort="5"
      velocity="5" />
  </joint>
  <link
    name="FR_2">
    <inertial>
      <origin
        xyz="5.81463813074806E-05 0.0372579060064524 -0.0440057362809116"
        rpy="0 0 0" />
      <mass
        value="0.955322690779101" />
      <inertia
        ixx="0.00135382463322311"
        ixy="2.40549276637862E-07"
        ixz="-1.30902180553742E-06"
        iyy="0.00173666668372863"
        iyz="1.02515334146085E-05"
        izz="0.000526624906422333" />
    </inertial>
    <visual>
      <origin
        xyz="0 0 0"
        rpy="0 0 0" />
      <geometry>
        <mesh
          filename="package://nuDogv6/meshes/FR_2.STL" />
      </geometry>
      <material
        name="">
        <color
          rgba="0.792156862745098 0.819607843137255 0.933333333333333 1" />
      </material>
    </visual>
    <collision>
      <origin
        xyz="0 0 0"
        rpy="0 0 0" />
      <geometry>
        <mesh
          filename="package://nuDogv6/meshes/FR_2.STL" />
      </geometry>
    </collision>
  </link>
  <joint
    name="FR_Hip"
    type="revolute">
    <origin
      xyz="-0.087 0.04635 0"
      rpy="0 0 0" />
    <parent
      link="FR_1" />
    <child
      link="FR_2" />
    <axis
      xyz="0 1 0" />
    <limit
      lower="-5"
      upper="5"
      effort="5"
      velocity="5" />
  </joint>
  <link
    name="FR_3">
    <inertial>
      <origin
        xyz="-0.00219267056994654 -0.0292079279218723 -0.0840068646168993"
        rpy="0 0 0" />
      <mass
        value="0.343745471195329" />
      <inertia
        ixx="0.000820436232498093"
        ixy="-2.63187495677138E-10"
        ixz="-7.02033420128806E-10"
        iyy="0.000845273980989468"
        iyz="3.31672239367909E-10"
        izz="6.00811902101851E-05" />
    </inertial>
    <visual>
      <origin
        xyz="0 0 0"
        rpy="0 0 0" />
      <geometry>
        <mesh
          filename="package://nuDogv6/meshes/FR_3.STL" />
      </geometry>
      <material
        name="">
        <color
          rgba="0.647058823529412 0.619607843137255 0.588235294117647 1" />
      </material>
    </visual>
    <collision>
      <origin
        xyz="0 0 0"
        rpy="0 0 0" />
      <geometry>
        <mesh
          filename="package://nuDogv6/meshes/FR_3.STL" />
      </geometry>
    </collision>
  </link>
  <joint
    name="FR_Knee"
    type="revolute">
    <origin
      xyz="0.002279 0.089024 -0.3055"
      rpy="0 0 0" />
    <parent
      link="FR_2" />
    <child
      link="FR_3" />
    <axis
      xyz="0 1 0" />
    <limit
      lower="-5"
      upper="5"
      effort="5"
      velocity="5" />
  </joint>
  <link
    name="FR_F">
    <inertial>
      <origin
        xyz="0 -5.55111512312578E-17 0.00908903172798536"
        rpy="0 0 0" />
      <mass
        value="0.0795066908433816" />
      <inertia
        ixx="3.6051507112722E-05"
        ixy="1.26933505587961E-21"
        ixz="2.31568806981652E-21"
        iyy="3.60278364502836E-05"
        iyz="-4.49769709525602E-21"
        izz="1.74581184916402E-05" />
    </inertial>
    <visual>
      <origin
        xyz="0 0 0"
        rpy="0 0 0" />
      <geometry>
        <mesh
          filename="package://nuDogv6/meshes/FR_F.STL" />
      </geometry>
      <material
        name="">
        <color
          rgba="0.792156862745098 0.819607843137255 0.933333333333333 1" />
      </material>
    </visual>
    <collision>
      <origin
        xyz="0 0 0"
        rpy="0 0 0" />
      <geometry>
        <mesh
          filename="package://nuDogv6/meshes/FR_F.STL" />
      </geometry>
    </collision>
  </link>
  <joint
    name="FR_Ank"
    type="fixed">
    <origin
      xyz="-0.002679 -0.029112 -0.30696"
      rpy="0 0 0" />
    <parent
      link="FR_3" />
    <child
      link="FR_F" />
    <axis
      xyz="0 0 0" />
  </joint>
  <link
    name="FL_1">
    <inertial>
      <origin
        xyz="-0.0967393972118638 0.000926541484217031 -0.00199756778760267"
        rpy="0 0 0" />
      <mass
        value="0.555829934213579" />
      <inertia
        ixx="0.000517470888264942"
        ixy="-1.34557888211724E-05"
        ixz="1.89099545530415E-05"
        iyy="0.00142784443930778"
        iyz="2.61316343241059E-06"
        izz="0.00108178897095405" />
    </inertial>
    <visual>
      <origin
        xyz="0 0 0"
        rpy="0 0 0" />
      <geometry>
        <mesh
          filename="package://nuDogv6/meshes/FL_1.STL" />
      </geometry>
      <material
        name="">
        <color
          rgba="0.792156862745098 0.819607843137255 0.933333333333333 1" />
      </material>
    </visual>
    <collision>
      <origin
        xyz="0 0 0"
        rpy="0 0 0" />
      <geometry>
        <mesh
          filename="package://nuDogv6/meshes/FL_1.STL" />
      </geometry>
    </collision>
  </link>
  <joint
    name="FL_Ad"
    type="revolute">
    <origin
      xyz="-0.2 -0.19035 0.52"
      rpy="0 0 -1.5708" />
    <parent
      link="Body" />
    <child
      link="FL_1" />
    <axis
      xyz="1 0 0" />
    <limit
      lower="-5"
      upper="5"
      effort="5"
      velocity="5" />
  </joint>
  <link
    name="FL_2">
    <inertial>
      <origin
        xyz="-5.81457989127093E-05 -0.0372579050307496 -0.0440057423429025"
        rpy="0 0 0" />
      <mass
        value="0.95532258679353" />
      <inertia
        ixx="0.00135382460982778"
        ixy="2.40547375722133E-07"
        ixz="1.30901613565249E-06"
        iyy="0.00173666666102497"
        iyz="-1.02515223942036E-05"
        izz="0.000526624901498985" />
    </inertial>
    <visual>
      <origin
        xyz="0 0 0"
        rpy="0 0 0" />
      <geometry>
        <mesh
          filename="package://nuDogv6/meshes/FL_2.STL" />
      </geometry>
      <material
        name="">
        <color
          rgba="0.792156862745098 0.819607843137255 0.933333333333333 1" />
      </material>
    </visual>
    <collision>
      <origin
        xyz="0 0 0"
        rpy="0 0 0" />
      <geometry>
        <mesh
          filename="package://nuDogv6/meshes/FL_2.STL" />
      </geometry>
    </collision>
  </link>
  <joint
    name="FL_Hip"
    type="revolute">
    <origin
      xyz="-0.087 -0.04635 0"
      rpy="0 0 0" />
    <parent
      link="FL_1" />
    <child
      link="FL_2" />
    <axis
      xyz="0 1 0" />
    <limit
      lower="-5"
      upper="5"
      effort="5"
      velocity="5" />
  </joint>
  <link
    name="FL_3">
    <inertial>
      <origin
        xyz="-0.00236534514654632 -0.641540072077353 -0.0840068629159584"
        rpy="0 0 0" />
      <mass
        value="0.343745471145017" />
      <inertia
        ixx="0.000820436232454408"
        ixy="-2.64441127911884E-10"
        ixz="7.02124372057975E-10"
        iyy="0.000845273980971351"
        iyz="-3.2333683140782E-10"
        izz="6.00811902369714E-05" />
    </inertial>
    <visual>
      <origin
        xyz="0 0 0"
        rpy="0 0 0" />
      <geometry>
        <mesh
          filename="package://nuDogv6/meshes/FL_3.STL" />
      </geometry>
      <material
        name="">
        <color
          rgba="0.192156862745098 0.203921568627451 0.203921568627451 1" />
      </material>
    </visual>
    <collision>
      <origin
        xyz="0 0 0"
        rpy="0 0 0" />
      <geometry>
        <mesh
          filename="package://nuDogv6/meshes/FL_3.STL" />
      </geometry>
    </collision>
  </link>
  <joint
    name="FL_Knee"
    type="revolute">
    <origin
      xyz="0.002279 0.58172 -0.3055"
      rpy="0 0 0" />
    <parent
      link="FL_2" />
    <child
      link="FL_3" />
    <axis
      xyz="0 1 0" />
    <limit
      lower="-5"
      upper="5"
      effort="5"
      velocity="5" />
  </joint>
  <link
    name="FL_F">
    <inertial>
      <origin
        xyz="2.77555756156289E-16 -5.55111512312578E-17 0.00908903172798525"
        rpy="0 0 0" />
      <mass
        value="0.0795066908433817" />
      <inertia
        ixx="3.60515071127221E-05"
        ixy="-2.52615659684742E-21"
        ixz="-5.48010711639832E-19"
        iyy="3.60278364502837E-05"
        iyz="1.91845975460051E-20"
        izz="1.74581184916402E-05" />
    </inertial>
    <visual>
      <origin
        xyz="0 0 0"
        rpy="0 0 0" />
      <geometry>
        <mesh
          filename="package://nuDogv6/meshes/FL_F.STL" />
      </geometry>
      <material
        name="">
        <color
          rgba="0.792156862745098 0.819607843137255 0.933333333333333 1" />
      </material>
    </visual>
    <collision>
      <origin
        xyz="0 0 0"
        rpy="0 0 0" />
      <geometry>
        <mesh
          filename="package://nuDogv6/meshes/FL_F.STL" />
      </geometry>
    </collision>
  </link>
  <joint
    name="FL_Ank"
    type="fixed">
    <origin
      xyz="-0.00187901353150022 -0.641635499999994 -0.306958515898266"
      rpy="0 0 0" />
    <parent
      link="FL_3" />
    <child
      link="FL_F" />
    <axis
      xyz="0 0 0" />
  </joint>
  <link
    name="BR_1">
    <inertial>
      <origin
        xyz="0.0967393972118642 -0.000926541484217086 -0.00199756778760245"
        rpy="0 0 0" />
      <mass
        value="0.55582993421358" />
      <inertia
        ixx="0.000517470888264942"
        ixy="-1.34557888211724E-05"
        ixz="-1.89099545530413E-05"
        iyy="0.00142784443930778"
        iyz="-2.61316343241065E-06"
        izz="0.00108178897095405" />
    </inertial>
    <visual>
      <origin
        xyz="0 0 0"
        rpy="0 0 0" />
      <geometry>
        <mesh
          filename="package://nuDogv6/meshes/BR_1.STL" />
      </geometry>
      <material
        name="">
        <color
          rgba="0.792156862745098 0.819607843137255 0.933333333333333 1" />
      </material>
    </visual>
    <collision>
      <origin
        xyz="0 0 0"
        rpy="0 0 0" />
      <geometry>
        <mesh
          filename="package://nuDogv6/meshes/BR_1.STL" />
      </geometry>
    </collision>
  </link>
  <joint
    name="BR_Ad"
    type="revolute">
    <origin
      xyz="0.2 -0.72405 0.52"
      rpy="0 0 -1.5708" />
    <parent
      link="Body" />
    <child
      link="BR_1" />
    <axis
      xyz="1 0 0" />
    <limit
      lower="-5"
      upper="5"
      effort="5"
      velocity="5" />
  </joint>
  <link
    name="BR_2">
    <inertial>
      <origin
        xyz="5.81461943445216E-05 0.0372579044894271 -0.0440057435331936"
        rpy="0 0 0" />
      <mass
        value="0.955322554598998" />
      <inertia
        ixx="0.00135382460653267"
        ixy="2.40548192964037E-07"
        ixz="-1.3090174102698E-06"
        iyy="0.00173666665883878"
        iyz="1.02515233497371E-05"
        izz="0.000526624896799295" />
    </inertial>
    <visual>
      <origin
        xyz="0 0 0"
        rpy="0 0 0" />
      <geometry>
        <mesh
          filename="package://nuDogv6/meshes/BR_2.STL" />
      </geometry>
      <material
        name="">
        <color
          rgba="0.792156862745098 0.819607843137255 0.933333333333333 1" />
      </material>
    </visual>
    <collision>
      <origin
        xyz="0 0 0"
        rpy="0 0 0" />
      <geometry>
        <mesh
          filename="package://nuDogv6/meshes/BR_2.STL" />
      </geometry>
    </collision>
  </link>
  <joint
    name="BR_Hip"
    type="revolute">
    <origin
      xyz="0.087 0.04635 0"
      rpy="0 0 0" />
    <parent
      link="BR_1" />
    <child
      link="BR_2" />
    <axis
      xyz="0 1 0" />
    <limit
      lower="-5"
      upper="5"
      effort="5"
      velocity="5" />
  </joint>
  <link
    name="BR_3">
    <inertial>
      <origin
        xyz="-0.00216310580978896 -0.0288985313659216 -0.0828567968449873"
        rpy="0 0 0" />
      <mass
        value="0.343745471154525" />
      <inertia
        ixx="0.000820436232500881"
        ixy="-2.63187347861388E-10"
        ixz="-7.02034865420379E-10"
        iyy="0.00084527398098969"
        iyz="3.31671934273074E-10"
        izz="6.00811902075226E-05" />
    </inertial>
    <visual>
      <origin
        xyz="0 0 0"
        rpy="0 0 0" />
      <geometry>
        <mesh
          filename="package://nuDogv6/meshes/BR_3.STL" />
      </geometry>
      <material
        name="">
        <color
          rgba="0.647058823529412 0.619607843137255 0.588235294117647 1" />
      </material>
    </visual>
    <collision>
      <origin
        xyz="0 0 0"
        rpy="0 0 0" />
      <geometry>
        <mesh
          filename="package://nuDogv6/meshes/BR_3.STL" />
      </geometry>
    </collision>
  </link>
  <joint
    name="BR_Knee"
    type="revolute">
    <origin
      xyz="0.0022494 0.088715 -0.30665"
      rpy="0 0 0" />
    <parent
      link="BR_2" />
    <child
      link="BR_3" />
    <axis
      xyz="0 1 0" />
    <limit
      lower="-5"
      upper="5"
      effort="5"
      velocity="5" />
  </joint>
  <link
    name="BR_F">
    <inertial>
      <origin
        xyz="0 -5.55111512312578E-17 0.00908903172798536"
        rpy="0 0 0" />
      <mass
        value="0.0795066908433816" />
      <inertia
        ixx="3.6051507112722E-05"
        ixy="4.07169749404491E-21"
        ixz="4.68978553204609E-21"
        iyy="3.60278364502836E-05"
        iyz="4.82829595830121E-21"
        izz="1.74581184916402E-05" />
    </inertial>
    <visual>
      <origin
        xyz="0 0 0"
        rpy="0 0 0" />
      <geometry>
        <mesh
          filename="package://nuDogv6/meshes/BR_F.STL" />
      </geometry>
      <material
        name="">
        <color
          rgba="0.792156862745098 0.819607843137255 0.933333333333333 1" />
      </material>
    </visual>
    <collision>
      <origin
        xyz="0 0 0"
        rpy="0 0 0" />
      <geometry>
        <mesh
          filename="package://nuDogv6/meshes/BR_F.STL" />
      </geometry>
    </collision>
  </link>
  <joint
    name="BR_Ank"
    type="fixed">
    <origin
      xyz="-0.00264944876959738 -0.0288031034448313 -0.30580844811589"
      rpy="0 0 0" />
    <parent
      link="BR_3" />
    <child
      link="BR_F" />
    <axis
      xyz="0 0 0" />
  </joint>
  <link
    name="BL_1">
    <inertial>
      <origin
        xyz="0.0966409614939927 0.000926528715806146 -0.00199755966138066"
        rpy="0 0 0" />
      <mass
        value="0.555831049727418" />
      <inertia
        ixx="0.000517471328500525"
        ixy="1.30651234728157E-05"
        ixz="-1.88139667336106E-05"
        iyy="0.0014278472958104"
        iyz="2.61322353699524E-06"
        izz="0.0010817875905303" />
    </inertial>
    <visual>
      <origin
        xyz="0 0 0"
        rpy="0 0 0" />
      <geometry>
        <mesh
          filename="package://nuDogv6/meshes/BL_1.STL" />
      </geometry>
      <material
        name="">
        <color
          rgba="0.792156862745098 0.819607843137255 0.933333333333333 1" />
      </material>
    </visual>
    <collision>
      <origin
        xyz="0 0 0"
        rpy="0 0 0" />
      <geometry>
        <mesh
          filename="package://nuDogv6/meshes/BL_1.STL" />
      </geometry>
    </collision>
  </link>
  <joint
    name="BL_Ad"
    type="revolute">
    <origin
      xyz="-0.2 -0.72405 0.52"
      rpy="0 0 -1.5708" />
    <parent
      link="Body" />
    <child
      link="BL_1" />
    <axis
      xyz="1 0 0" />
    <limit
      lower="-5"
      upper="5"
      effort="5"
      velocity="5" />
  </joint>
  <link
    name="BL_2">
    <inertial>
      <origin
        xyz="-5.81457906760896E-05 -0.037257904737137 -0.044005743574709"
        rpy="0 0 0" />
      <mass
        value="0.955322567136384" />
      <inertia
        ixx="0.00135382460838233"
        ixy="2.40547213632294E-07"
        ixz="1.30901540297894E-06"
        iyy="0.00173666665936499"
        iyz="-1.02515223830775E-05"
        izz="0.000526624901311548" />
    </inertial>
    <visual>
      <origin
        xyz="0 0 0"
        rpy="0 0 0" />
      <geometry>
        <mesh
          filename="package://nuDogv6/meshes/BL_2.STL" />
      </geometry>
      <material
        name="">
        <color
          rgba="0.792156862745098 0.819607843137255 0.933333333333333 1" />
      </material>
    </visual>
    <collision>
      <origin
        xyz="0 0 0"
        rpy="0 0 0" />
      <geometry>
        <mesh
          filename="package://nuDogv6/meshes/BL_2.STL" />
      </geometry>
    </collision>
  </link>
  <joint
    name="BL_Hip"
    type="revolute">
    <origin
      xyz="0.087 -0.04635 0"
      rpy="0 0 0" />
    <parent
      link="BL_1" />
    <child
      link="BL_2" />
    <axis
      xyz="0 1 0" />
    <limit
      lower="-5"
      upper="5"
      effort="5"
      velocity="5" />
  </joint>
  <link
    name="BL_3">
    <inertial>
      <origin
        xyz="0.00247230675800469 0.0292079279148152 -0.0828445925712516"
        rpy="0 0 0" />
      <mass
        value="0.34374547124735" />
      <inertia
        ixx="0.000820436232471936"
        ixy="-2.644426577013E-10"
        ixz="7.02123149864262E-10"
        iyy="0.000845273980989403"
        iyz="-3.23337732521285E-10"
        izz="6.00811902371145E-05" />
    </inertial>
    <visual>
      <origin
        xyz="0 0 0"
        rpy="0 0 0" />
      <geometry>
        <mesh
          filename="package://nuDogv6/meshes/BL_3.STL" />
      </geometry>
      <material
        name="">
        <color
          rgba="0.192156862745098 0.203921568627451 0.203921568627451 1" />
      </material>
    </visual>
    <collision>
      <origin
        xyz="0 0 0"
        rpy="0 0 0" />
      <geometry>
        <mesh
          filename="package://nuDogv6/meshes/BL_3.STL" />
      </geometry>
    </collision>
  </link>
  <joint
    name="BL_Knee"
    type="revolute">
    <origin
      xyz="-0.0025586 -0.089024 -0.30666"
      rpy="0 0 0" />
    <parent
      link="BL_2" />
    <child
      link="BL_3" />
    <axis
      xyz="0 1 0" />
    <limit
      lower="-5"
      upper="5"
      effort="5"
      velocity="5" />
  </joint>
  <link
    name="BL_F">
    <inertial>
      <origin
        xyz="1.11022302462516E-16 5.55111512312578E-17 0.00908903172798536"
        rpy="0 0 0" />
      <mass
        value="0.0795066908433817" />
      <inertia
        ixx="3.60515071127221E-05"
        ixy="-5.60983218608841E-21"
        ixz="-5.31880804195034E-19"
        iyy="3.60278364502837E-05"
        iyz="-1.17679964786894E-21"
        izz="1.74581184916402E-05" />
    </inertial>
    <visual>
      <origin
        xyz="0 0 0"
        rpy="0 0 0" />
      <geometry>
        <mesh
          filename="package://nuDogv6/meshes/BL_F.STL" />
      </geometry>
      <material
        name="">
        <color
          rgba="0.792156862745098 0.819607843137255 0.933333333333333 1" />
      </material>
    </visual>
    <collision>
      <origin
        xyz="0 0 0"
        rpy="0 0 0" />
      <geometry>
        <mesh
          filename="package://nuDogv6/meshes/BL_F.STL" />
      </geometry>
    </collision>
  </link>
  <joint
    name="BL_Ank"
    type="fixed">
    <origin
      xyz="0.00295863837265653 0.0291125000000009 -0.305796245573505"
      rpy="0 0 0" />
    <parent
      link="BL_3" />
    <child
      link="BL_F" />
    <axis
      xyz="0 0 0" />
  </joint>
</robot>
